<?xml version="1.0" encoding="utf-8"?>
<!-- This URDF was automatically created by SolidWorks to URDF Exporter! Originally created by Stephen Brawner (brawner@gmail.com) 
     Commit Version: 1.6.0-4-g7f85cfe  Build Version: 1.6.7995.38578
     For more information, please see http://wiki.ros.org/sw_urdf_exporter -->
<robot
  name="revac stimulation">
  <link
    name="base_link">
    <inertial>
      <origin
        xyz="-2.25327892239033E-19 7.88045267673459E-19 -0.0100000000000001"
        rpy="0 0 0" />
      <mass
        value="2.10094008708817" />
      <inertia
        ixx="0.0328446966948118"
        ixy="-3.08150586211115E-20"
        ixz="-1.9578173228708E-17"
        iyy="0.0328446966948118"
        iyz="-1.26954068177143E-18"
        izz="0.0656543777215054" />
    </inertial>
    <visual>
      <origin
        xyz="0 0 0"
        rpy="0 0 0" />
      <geometry>
        <mesh
          filename="package://revac stimulation/meshes/base_link.STL" />
      </geometry>
      <material
        name="">
        <color
          rgba="1 1 1 0.32" />
      </material>
    </visual>
    <collision>
      <origin
        xyz="0 0 0"
        rpy="0 0 0" />
      <geometry>
        <mesh
          filename="package://revac stimulation/meshes/base_link.STL" />
      </geometry>
    </collision>
  </link>
  <link
    name="link_1">
    <inertial>
      <origin
        xyz="2.2723E-07 -5.1802E-08 0.3784"
        rpy="0 0 0" />
      <mass
        value="12.771" />
      <inertia
        ixx="1.1288"
        ixy="-1.3688E-06"
        ixz="-9.007E-07"
        iyy="1.1271"
        iyz="3.6139E-07"
        izz="0.15316" />
    </inertial>
    <visual>
      <origin
        xyz="0 0 0"
        rpy="0 0 0" />
      <geometry>
        <mesh
          filename="package://revac stimulation/meshes/link_1.STL" />
      </geometry>
      <material
        name="">
        <color
          rgba="0.64706 0.51765 0 1" />
      </material>
    </visual>
    <collision>
      <origin
        xyz="0 0 0"
        rpy="0 0 0" />
      <geometry>
        <mesh
          filename="package://revac stimulation/meshes/link_1.STL" />
      </geometry>
    </collision>
  </link>
  <joint
    name="joint_1"
    type="continuous">
    <origin
      xyz="0 0 0"
      rpy="1.5708 0.84289 0" />
    <parent
      link="base_link" />
    <child
      link="link_1" />
    <axis
      xyz="0 0 1" />
  </joint>
  <link
    name="link_2">
    <inertial>
      <origin
        xyz="-0.3815 7.8639E-07 -4.6615E-07"
        rpy="0 0 0" />
      <mass
        value="10.002" />
      <inertia
        ixx="0.082045"
        ixy="-2.0367E-07"
        ixz="5.3319E-08"
        iyy="0.62308"
        iyz="-1.1786E-06"
        izz="0.62631" />
    </inertial>
    <visual>
      <origin
        xyz="0 0 0"
        rpy="0 0 0" />
      <geometry>
        <mesh
          filename="package://revac stimulation/meshes/link_2.STL" />
      </geometry>
      <material
        name="">
        <color
          rgba="1 1 1 0.32" />
      </material>
    </visual>
    <collision>
      <origin
        xyz="0 0 0"
        rpy="0 0 0" />
      <geometry>
        <mesh
          filename="package://revac stimulation/meshes/link_2.STL" />
      </geometry>
    </collision>
  </link>
  <joint
    name="joint_2"
    type="continuous">
    <origin
      xyz="-0.21 0.36186 1.5217"
      rpy="-1.5708 -1.0767 1.5708" />
    <parent
      link="link_1" />
    <child
      link="link_2" />
    <axis
      xyz="0 0 1" />
    <limit
      lower="-1.574"
      upper="1.574"
      effort="0"
      velocity="0" />
  </joint>
  <link
    name="link_3">
    <inertial>
      <origin
        xyz="-0.35625 -7.0544E-07 2.9644E-06"
        rpy="0 0 0" />
      <mass
        value="9.3902" />
      <inertia
        ixx="0.077033"
        ixy="-5.6769E-07"
        ixz="-9.5696E-07"
        iyy="0.52154"
        iyz="-1.0923E-06"
        izz="0.52477" />
    </inertial>
    <visual>
      <origin
        xyz="0 0 0"
        rpy="0 0 0" />
      <geometry>
        <mesh
          filename="package://revac stimulation/meshes/link_3.STL" />
      </geometry>
      <material
        name="">
        <color
          rgba="0.1098 0.1098 0.1098 1" />
      </material>
    </visual>
    <collision>
      <origin
        xyz="0 0 0"
        rpy="0 0 0" />
      <geometry>
        <mesh
          filename="package://revac stimulation/meshes/link_3.STL" />
      </geometry>
    </collision>
  </link>
  <joint
    name="joint_3"
    type="continuous">
    <origin
      xyz="-0.56816 0.42995 -0.21"
      rpy="0 0 2.4938" />
    <parent
      link="link_2" />
    <child
      link="link_3" />
    <axis
      xyz="0 0 1" />
  </joint>
  <link
    name="link_4">
    <inertial>
      <origin
        xyz="-0.1465 4.2537E-06 5.5927E-06"
        rpy="0 0 0" />
      <mass
        value="1.2198" />
      <inertia
        ixx="0.0037245"
        ixy="1.6306E-07"
        ixz="6.5008E-08"
        iyy="0.015462"
        iyz="-5.9823E-08"
        izz="0.015463" />
    </inertial>
    <visual>
      <origin
        xyz="0 0 0"
        rpy="0 0 0" />
      <geometry>
        <mesh
          filename="package://revac stimulation/meshes/link_4.STL" />
      </geometry>
      <material
        name="">
        <color
          rgba="1 1 1 0.32" />
      </material>
    </visual>
    <collision>
      <origin
        xyz="0 0 0"
        rpy="0 0 0" />
      <geometry>
        <mesh
          filename="package://revac stimulation/meshes/link_4.STL" />
      </geometry>
    </collision>
  </link>
  <joint
    name="joint_4"
    type="continuous">
    <origin
      xyz="0.047395 -0.28914 -0.17"
      rpy="0 0 -1.4083" />
    <parent
      link="link_3" />
    <child
      link="link_4" />
    <axis
      xyz="0 0 1" />
    <limit
      lower="-1.574"
      upper="1.574"
      effort="0"
      velocity="0" />
  </joint>
  <link
    name="link_5">
    <inertial>
      <origin
        xyz="0.085377 -2.1812E-06 7.1936E-07"
        rpy="0 0 0" />
      <mass
        value="0.89166" />
      <inertia
        ixx="0.0025705"
        ixy="-3.0153E-08"
        ixz="-1.2401E-08"
        iyy="0.005179"
        iyz="-9.3489E-09"
        izz="0.005431" />
    </inertial>
    <visual>
      <origin
        xyz="0 0 0"
        rpy="0 0 0" />
      <geometry>
        <mesh
          filename="package://revac stimulation/meshes/link_5.STL" />
      </geometry>
      <material
        name="">
        <color
          rgba="1 1 1 0.32" />
      </material>
    </visual>
    <collision>
      <origin
        xyz="0 0 0"
        rpy="0 0 0" />
      <geometry>
        <mesh
          filename="package://revac stimulation/meshes/link_5.STL" />
      </geometry>
    </collision>
  </link>
  <joint
    name="joint_5"
    type="continuous">
    <origin
      xyz="0 -0.13 0"
      rpy="1.5708 -0.050805 0" />
    <parent
      link="link_4" />
    <child
      link="link_5" />
    <axis
      xyz="0 0 1" />
  </joint>
  <link
    name="link_6">
    <inertial>
      <origin
        xyz="2.2204E-16 -1.1102E-16 0.085579"
        rpy="0 0 0" />
      <mass
        value="0.40674" />
      <inertia
        ixx="0.0012031"
        ixy="5.421E-20"
        ixz="8.1527E-20"
        iyy="0.0012031"
        iyz="2.666E-19"
        izz="0.00048422" />
    </inertial>
    <visual>
      <origin
        xyz="0 0 0"
        rpy="0 0 0" />
      <geometry>
        <mesh
          filename="package://revac stimulation/meshes/link_6.STL" />
      </geometry>
      <material
        name="">
        <color
          rgba="1 1 1 0.32" />
      </material>
    </visual>
    <collision>
      <origin
        xyz="0 0 0"
        rpy="0 0 0" />
      <geometry>
        <mesh
          filename="package://revac stimulation/meshes/link_6.STL" />
      </geometry>
    </collision>
  </link>
  <joint
    name="joint_6"
    type="continuous">
    <origin
      xyz="0.080883 0 0"
      rpy="1.5708 0.61816 1.5708" />
    <parent
      link="link_5" />
    <child
      link="link_6" />
    <axis
      xyz="0 0 1" />
  </joint>
</robot>